tests/fixtures/malformed_data.csv
timestamp,symbol,price,size,side,source
2026-09-16T10:00:00.100000000Z,AAPL,150.25,100,BUY,NASDAQ
INVALID_TIMESTAMP_LINE,AAPL,150.30,250,SELL,NASDAQ
2026-09-16T10:00:00.300000000Z,,150.28,50,BUY,NASDAQ
2026-09-16T10:00:00.400000000Z,AAPL,-10.00,100,BUY,NASDAQ
2026-09-16T10:00:00.500000000Z,AAPL,150.50,0,BUY,NASDAQ
CORRUPT_COLUMN_COUNT,TOO_FEW_COLUMNS
2026-09-16T10:00:00.600000000Z,AAPL,150.75,200,BUY,NASDAQ
