tests/fixtures/sample_quotes.jsonl
{"timestamp": "2026-09-16T10:00:00.050000000Z", "symbol": "AAPL", "bid_price": "150.20", "bid_size": "500", "ask_price": "150.25", "ask_size": "600", "source": "NASDAQ"}
{"timestamp": "2026-09-16T10:00:00.150000000Z", "symbol": "AAPL", "bid_price": "150.22", "bid_size": "400", "ask_price": "150.28", "ask_size": "300", "source": "NASDAQ"}
